Workbook

Sheet FINAL MAP
A1: URL | B1: Title | C1: Key | H1: Definition of Sycophancy (what exactly do they mean by sycophancy) | M1: Outcomes (Are they measuring the impact of sycophancy on something else?)
E2: Human - Specialist | F2: Human - Authors | G2: AI - prompted | H2: Hallucination Agreement | I2: Bias Agreement | J2: Obsequiousness | K2: Stance Change | L2: Failure to challenge/trying to get along | M2: None | N2: User opinion | O2: User action | P2: System performance | Q2: User performance
E3: Having someone with expertise (psychologist, conversation expert, etc) judge | F3: Authors judging | G3: Some sort of prompted AI doing the judging | H3: Saying something objectively wrong/harmful becuase the user wants it to be so | I3: The LLM choosing something that isn't objectively wrong, but siding towards the version that it believes user would want | J3: Fawning or overly positive language | K3: Getting the LLM to change opinions/stance/viewpoint to please/mirror user | L3: LLM failing to push back or challenge user or just going along with user's suggestion despite potential problems | M3: Just measuing sycophancy directly with no impact | N3: Measuring how users feel/react in some way | O3: Measuring something about how users behave while/after interacting with sycophantic LLMS | P3: Some measure of how sycophantic LLMs perform on some task | Q3: Some measure of how well the user is able to accomplish a task with sycophantic/non-sycophantic agents
A4: https://ieeexplore.ieee.org/stamp/stamp.jsp?arnumber=11449950 | B4: Too Positive to Be True? Sentiment Analysis of AI-Guided vs. Human-Led Debriefings in Virtual Reality Counseling Training | C4: 10.1109/AIxVR67263.2026.00026 | G4: X | J4: X | L4: X | O4: X
A5: https://ieeexplore.ieee.org/stamp/stamp.jsp?arnumber=10825538 | B5: Mitigating Sycophancy in Large Language Models via Direct Preference Optimization | C5: 10.1109/BigData62323.2024.10825538 | G5: X | K5: X | L5: X | P5: X
A6: https://ieeexplore.ieee.org/stamp/stamp.jsp?arnumber=11460702 | B6: Towards Self-Evaluation of Sycophantic Hallucinations in Mathematical Reasoning | C6: 10.1109/ICASSP55912.2026.11460702 | G6: X | H6: X | K6: X | L6: X | P6: X
A7: https://ieeexplore.ieee.org/stamp/stamp.jsp?arnumber=10820709 | B7: SciTrust: Evaluating the Trustworthiness of Large Language Models for Science | C7: 10.1109/SCW63240.2024.00017 | F7: X | G7: X | H7: X | P7: X
A8: https://doi.org/10.1145/1518701.1519021 | B8: I'm sorry | C8: 10.1145/1518701.1519021 | L8: X | N8: X | O8: X
A9: https://doi.org/10.1145/3660650.3660656 | B9: Faceless Adversary | C9: 10.1145/3660650.3660656 | E9: X | J9: X | L9: X | M9: X
A10: https://doi.org/10.1145/3663547.3746319 | B10: Probing the Gaps in ChatGPT's Live Video Chat for Real-World Assistance for People who are Blind or Visually Impaired | C10: 10.1145/3663547.3746319 | F10: X | L10: X | N10: X | O10: X
A11: https://doi.org/10.1145/3703155 | B11: A Survey on Hallucination in Large Language Models: Principles | C11: 10.1145/3703155 | E11: X | H11: X | L11: X | P11: X
A12: https://doi.org/10.1145/3706599.3719976 | B12: Exploring Older Adults Personality Preferences for LLM-powered Conversational Companions | C12: 10.1145/3706599.3719976 | I12: X | L12: X | N12: X
A13: https://doi.org/10.1145/3715275.3732039 | B13: Expressing stigma and inappropriate responses prevents LLMs from safely replacing mental health providers. | C13: 10.1145/3715275.3732039 | E13: X | G13: X | L13: X | P13: X
A14: https://doi.org/10.1145/3717511.3747073 | B14: Interactive Social Agent Behaviors of Politeness and Compromise in Collaborative Decision-making | C14: 10.1145/3717511.3747073 | I14: X | L14: X | Q14: X
A15: https://doi.org/10.1145/3719160.3736618 | B15: Navigating the Fog: How University Students Recalibrate Sensemaking Practices to Address Plausible Falsehoods in LLM Outputs | C15: 10.1145/3719160.3736618 | K15: X | N15: X | O15: X
A16: https://doi.org/10.1145/3742413.3789120 | B16: Neural Transparency: Mechanistic Interpretability Interfaces for Anticipating Model Behaviors for Personalized AI | C16: 10.1145/3742413.3789120 | G16: X | L16: X | O16: X | Q16: X
A17: https://doi.org/10.1145/3744169.3744194 | B17: Reading the Praise/Prompt Machine: An Interface Criticism Approach to ChatGPT | C17: 10.1145/3744169.3744194 | F17: X | J17: X | L17: X | M17: X
A18: https://doi.org/10.1145/3746027.3755778 | B18: Evaluating and Mitigating Sycophancy in Large Vision-Language Models | C18: 10.1145/3746027.3755778 | F18: X | H18: X | K18: X | P18: X
A19: https://doi.org/10.1145/3772318.3790385 | B19: Understanding Compliance and Conversion Dynamics in Multi-Agent Collectives | C19: 10.1145/3772318.3790385 | K19: X | L19: X | N19: X | O19: X
A20: https://doi.org/10.1145/3772318.3790934 | B20: Does Sycophancy Change Decisions? Effect of LLM Sycophancy on AI-Assisted Decision-Making | C20: 10.1145/3772318.3790934 | I20: X | J20: X | N20: X | O20: X | Q20: X
A21: https://doi.org/10.1145/3772318.3791079 | B21: Be Friendly | C21: 10.1145/3772318.3791079 | J21: X | K21: X | N21: X
A22: https://doi.org/10.1145/3772318.3791149 | B22: The Siren Song of LLMs: How Users Perceive and Respond to Dark Patterns in Large Language Models | C22: 10.1145/3772318.3791149 | I22: X | J22: X | N22: X | O22: X
A23: https://doi.org/10.1145/3772318.3791233 | B23: When AI Gives Advice: Evaluating AI and Human Responses to Online Advice-Seeking for Well-Being | C23: 10.1145/3772318.3791233 | E23: X | I23: X | N23: X | P23: X
A24: https://doi.org/10.1145/3772318.3791300 | B24: All Accept | C24: 10.1145/3772318.3791300 | E24: X | I24: X | P24: X
A25: https://doi.org/10.1145/3772318.3791365 | B25: Invisible Saboteurs: Sycophantic LLMs Mislead Novices in Problem-Solving Tasks | C25: 10.1145/3772318.3791365 | L25: X | Q25: X
A26: https://doi.org/10.1145/3772318.3791851 | B26: Personal Validation Effect in LLMs: Positive AI Responses Bias Perceptions of Validity | C26: 10.1145/3772318.3791851 | I26: X | N26: X
A27: https://doi.org/10.1145/3772318.3791915 | B27: Interaction Context Often Increases Sycophancy in LLMs | C27: 10.1145/3772318.3791915 | I27: X | M27: X
A28: https://doi.org/10.1145/3772363.3798705 | B28: When AI Agrees | C28: 10.1145/3772363.3798705 | I28: X | N28: X
A29: https://doi.org/10.1145/3772363.3799334 | B29: Maintaining Stable Personas? Examining Temporal Stability in LLM-Based Human Simulation | C29: 10.1145/3772363.3799334 | F29: X | L29: X | P29: X
A30: https://doi.org/10.1145/3774904.3792506 | B30: Acting Flatterers via LLMs Sycophancy: Combating Clickbait with LLMs Opposing-Stance Reasoning | C30: 10.1145/3774904.3792506 | G30: X | I30: X | K30: X | P30: X
A31: https://doi.org/10.1145/3776734.3794532 | B31: Robotic Sycophancy: A Scoping Review | C31: 10.1145/3776734.3794532 | F31: X | I31: X | J31: X | L31: X | M31: X
A32: https://doi.org/10.1145/3786304.3787879 | B32: Confirmation | C32: 10.1145/3786304.3787879 | F32: X | I32: X | M32: X
A33: https://doi.org/10.1145/3786335.3813137 | B33: The Cost of Consensus: Isolated Self-Correction Prevails Over Unguided Homogeneous Multi-Agent Debate | C33: 10.1145/3786335.3813137 | F33: X | K33: X | P33: X
A34: https://doi.org/10.1145/3788646.3789536 | B34: AI-Assisted Moot Courts: Simulating Justice-Specific Questioning in Oral Arguments | C34: 10.1145/3788646.3789536 | G34: X | I34: X | L34: X | P34: X

Sheet All Papers
A1: URL | B1: DOI | C1: Title
A2: https://ieeexplore.ieee.org/stamp/stamp.jsp?arnumber=11460702 | B2: 10.1109/ICASSP55912.2026.11460702 | C2: Towards Self-Evaluation of Sycophantic Hallucinations in Mathematical Reasoning
A3: https://ieeexplore.ieee.org/stamp/stamp.jsp?arnumber=10825538 | B3: 10.1109/BigData62323.2024.10825538 | C3: Mitigating Sycophancy in Large Language Models via Direct Preference Optimization
A4: https://ieeexplore.ieee.org/stamp/stamp.jsp?arnumber=11424465 | B4: 10.1109/RAMS50514.2026.11424465 | C4: Autonomous AI-Driven FMEA Optimization For Safety And Reliability In Healthcare
A5: https://ieeexplore.ieee.org/stamp/stamp.jsp?arnumber=1431446 | B5: 10.1109/IRI.2004.1431446 | C5: Context learning can improve user interaction
A6: https://ieeexplore.ieee.org/stamp/stamp.jsp?arnumber=4299963 | B6: 10.1109/ICSEA.2007.67 | C6: Sycophant: An API for Research in Context-Aware User Interfaces
A7: https://ieeexplore.ieee.org/stamp/stamp.jsp?arnumber=735370 | B7: 10.1109/47.735370 | C7: The letter of submission: avoiding the promotional genre
A8: https://ieeexplore.ieee.org/stamp/stamp.jsp?arnumber=10771051 | B8: 10.1109/AIxSET62544.2024.00047 | C8: Towards Transparent Artificial Intelligence: Exploring Modern Approaches and Future Directions
A9: https://ieeexplore.ieee.org/stamp/stamp.jsp?arnumber=10590666 | B9: 10.1109/HPSC62738.2024.00012 | C9: Studying the Knowledge and Behavior of ChatGPT via Journey to the West
A10: https://ieeexplore.ieee.org/stamp/stamp.jsp?arnumber=11508939 | B10: 10.1109/ICAACE69793.2026.11508939 | C10: Tiny-Critic RAG: Empowering Agentic Fallback with Parameter-Efficient Small Language Models
A11: https://ieeexplore.ieee.org/stamp/stamp.jsp?arnumber=11345775 | B11: 10.1109/NKCon66957.2025.11345775 | C11: Improving Argumentative Reasoning in LLMs Using Online Debates and Agent-Based Interaction
A12: https://ieeexplore.ieee.org/stamp/stamp.jsp?arnumber=11462217 | B12: 10.1109/ICASSP55912.2026.11462217 | C12: FinLumen: A Game-Theoretic Multi-Agent Framework for Rational Portfolio Management
... A40: https://doi.org/10.1145/3746027.3755778 | B40: 10.1145/3746027.3755778 | C40: Evaluating and Mitigating Sycophancy in Large Vision-Language Models
A41: https://doi.org/10.1145/3772318.3791079 | B41: 10.1145/3772318.3791079 | C41: Be Friendly | D41: Not Friends: How LLM Sycophancy Shapes User Trust
A42: https://doi.org/10.1145/3772363.3798611 | B42: 10.1145/3772363.3798611 | C42: Verbalizing LLMs' Assumptions About the User to Calibrate Expectations and Reduce Sycophancy
A43: https://doi.org/10.1145/3772363.3798575 | B43: 10.1145/3772363.3798575 | C43: When Flattery Backfires: How Sycophancy and Interaction Context Shape Perceived Authenticity and Trust in Large Language AI Models
A44: https://doi.org/10.1145/3774904.3792506 | B44: 10.1145/3774904.3792506 | C44: Acting Flatterers via LLMs Sycophancy: Combating Clickbait with LLMs Opposing-Stance Reasoning
A45: https://doi.org/10.1145/3786335.3813137 | B45: 10.1145/3786335.3813137 | C45: The Cost of Consensus: Isolated Self-Correction Prevails Over Unguided Homogeneous Multi-Agent Debate
A46: https://doi.org/10.1145/3772363.3798923 | B46: 10.1145/3772363.3798923 | C46: ChatGPT Is a People Pleaser | D46: Especially When Taking Human vs. AI Advice
A47: https://doi.org/10.1145/3772363.3799156 | B47: 10.1145/3772363.3799156 | C47: Demoing Stochastic Parrot: A Candid AI Cohabitant
A48: https://doi.org/10.1145/3742413.3789120 | B48: 10.1145/3742413.3789120 | C48: Neural Transparency: Mechanistic Interpretability Interfaces for Anticipating Model Behaviors for Personalized AI
A49: https://doi.org/10.1145/3772318.3791233 | B49: 10.1145/3772318.3791233 | C49: When AI Gives Advice: Evaluating AI and Human Responses to Online Advice-Seeking for Well-Being
A50: https://doi.org/10.1145/3788646.3789536 | B50: 10.1145/3788646.3789536 | C50: AI-Assisted Moot Courts: Simulating Justice-Specific Questioning in Oral Arguments
A51: https://doi.org/10.1145/3719160.3736618 | B51: 10.1145/3719160.3736618 | C51: Navigating the Fog: How University Students Recalibrate Sensemaking Practices to Address Plausible Falsehoods in LLM Outputs
A52: https://doi.org/10.1145/3772318.3790739 | B52: 10.1145/3772318.3790739 | C52: Chat Should I Leave Him? Risks | D52: Rewards | E52: and Roles for AI in Relationship Advice
A53: https://doi.org/10.1109/SCW63240.2024.00017 | B53: 10.1109/SCW63240.2024.00017 | C53: SciTrust: Evaluating the Trustworthiness of Large Language Models for Science
A54: https://doi.org/10.1145/3715275.3732039 | B54: 10.1145/3715275.3732039 | C54: Expressing stigma and inappropriate responses prevents LLMs from safely replacing mental health providers.
A55: https://doi.org/10.1145/3663547.3746319 | B55: 10.1145/3663547.3746319 | C55: Probing the Gaps in ChatGPT's Live Video Chat for Real-World Assistance for People who are Blind or Visually Impaired
A56: https://doi.org/10.1145/3715070.3749272 | B56: 10.1145/3715070.3749272 | C56: Was there Bias in your Response?: LLM Anthropomorphic Traits in Context of Ability Bias Questioning
A57: https://doi.org/10.1145/3772318.3790279 | B57: 10.1145/3772318.3790279 | C57: Futuring Social Assemblages: How Enmeshing AIs into Social Life Challenges the Individual and the Interpersonal
A58: https://doi.org/10.1145/3772363.3798453 | B58: 10.1145/3772363.3798453 | C58: AI-Induced Delusional Spirals: Understanding Lived Experiences During Maladaptive Human-Chatbot Interactions
A59: https://doi.org/10.1145/3772318.3791149 | B59: 10.1145/3772318.3791149 | C59: The Siren Song of LLMs: How Users Perceive and Respond to Dark Patterns in Large Language Models
A60: https://doi.org/10.1145/3772318.3791851 | B60: 10.1145/3772318.3791851 | C60: Personal Validation Effect in LLMs: Positive AI Responses Bias Perceptions of Validity | D60: Reliability | E60: Personalization | F60: and Usefulness of Fictitious Predictions
A61: https://doi.org/10.1145/3772318.3791300 | B61: 10.1145/3772318.3791300 | C61: All Accept | D61: No Reject: Evaluating LLMs as “Peer” Reviewers
A62: https://doi.org/10.1145/3736731.3786118 | B62: 10.1145/3736731.3786118 | C62: Session Summary Podcast: Session 3: Posters
A63: https://doi.org/10.1145/3772318.3791775 | B63: 10.1145/3772318.3791775 | C63: From Symptoms to Systems: An Expert-Guided Approach to Understanding Risks of Generative AI for Eating Disorders
A64: https://doi.org/10.1145/3703155 | B64: 10.1145/3703155 | C64: A Survey on Hallucination in Large Language Models: Principles | D64: Taxonomy | E64: Challenges | F64: and Open Questions
A65: https://doi.org/10.1145/3765766.3765852 | B65: 10.1145/3765766.3765852 | C65: How Do People Evaluate Their Interactions with AI: A Qualitative Study of Emotionally Motivated AI Use and User Evaluation
A66: https://doi.org/10.1145/3746252.3761151 | B66: 10.1145/3746252.3761151 | C66: Where Does Legal AI Fail? Evaluating RAG Pipelines
A67: https://doi.org/10.1145/3706599.3719976 | B67: 10.1145/3706599.3719976 | C67: Exploring Older Adults Personality Preferences for LLM-powered Conversational Companions
...

Sheet INCEXC A
B1: key | D1: Evaluator Name | E1: Included/Excluded | F1: Excluded Reason | G1: Other
A2: https://doi.org/10.1007/978-3-642-24322-6_15 | B2: 10.1007/978-3-642-24322-6_15 | C2: The search for energy-efficient building blocks for the data center | D2: Jonathan | E2: Exclude | F2: Not about either LLMs or Sycophancy
A3: https://doi.org/10.1007/978-3-642-24322-6_16 | B3: 10.1007/978-3-642-24322-6_16 | C3: KnightShift: shifting the I/O burden in datacenters to management processor for energy efficiency | D3: Marilyn | E3: Exclude | F3: Not about either LLMs or Sycophancy
A4: https://doi.org/10.1007/978-3-642-24322-6_19 | B4: 10.1007/978-3-642-24322-6_19 | C4: Achieving power-efficiency in clusters without distributed file system complexity | D4: Marilyn | E4: Exclude | F4: Not about either LLMs or Sycophancy
A5: https://ieeexplore.ieee.org/stamp/stamp.jsp?arnumber=8372225 | B5: 10.1049/cp.2016.1548 | C5: A SOFC based autonomous microgrid performance analysis using adaptive PI and PI controller | D5: Marilyn | E5: Exclude | F5: Not about either LLMs or Sycophancy
A6: https://ieeexplore.ieee.org/stamp/stamp.jsp?arnumber=735370 | B6: 10.1109/47.735370 | C6: The letter of submission: avoiding the promotional genre | D6: Jonathan | E6: Exclude | F6: Not about either LLMs or Sycophancy
A7: https://ieeexplore.ieee.org/stamp/stamp.jsp?arnumber=11467909 | B7: 10.1109/ACDSA67686.2026.11467909 | C7: Evaluating LLM-Induced Investment Biases via Persona Design and Prompt Analysis: A Quantitative Study of Post-Retirement Asset Depletion Risk Through Social Simulation | D7: Marilyn | E7: Include | G7: Syncopancy in context of reinforcing individual investment biases
A8: https://ieeexplore.ieee.org/stamp/stamp.jsp?arnumber=10771051 | B8: 10.1109/AIxSET62544.2024.00047 | C8: Towards Transparent Artificial Intelligence: Exploring Modern Approaches and Future Directions | D8: Kaiser | E8: Exclude | F8: Not about Sycophancy
A9: https://ieeexplore.ieee.org/stamp/stamp.jsp?arnumber=11449950 | B9: 10.1109/AIxVR67263.2026.00026 | C9: Too Positive to Be True? Sentiment Analysis of AI-Guided vs. Human-Led Debriefings in Virtual Reality Counseling Training | D9: Kaiser | E9: Include
A10: https://ieeexplore.ieee.org/stamp/stamp.jsp?arnumber=11334577 | B10: 10.1109/ASE63991.2025.00043 | C10: Why AI Agents Still Need You: Findings from Developer-Agent Collaborations in the Wild | D10: Kaiser | E10: Exclude | F10: Not about Sycophancy
A11: https://ieeexplore.ieee.org/stamp/stamp.jsp?arnumber=9381292 | B11: 10.1109/ASONAM49781.2020.9381292 | C11: Aspect Based Abusive Sentiment Detection in Nepali Social Media Texts | D11: Jonathan | E11: Exclude | F11: Not about either LLMs or Sycophancy
A12: https://doi.org/10.1109/ASONAM49781.2020.9381292 | B12: 10.1109/asonam49781.2020.9381292 | C12: Aspect based abusive sentiment detection in nepali social media texts | D12: Marilyn | E12: Exclude | F12: Not about Sycophancy
A13: https://ieeexplore.ieee.org/stamp/stamp.jsp?arnumber=10825538 | B13: 10.1109/BigData62323.2024.10825538 | C13: Mitigating Sycophancy in Large Language Models via Direct Preference Optimization | D13: Kaiser | E13: Include
A14: https://ieeexplore.ieee.org/stamp/stamp.jsp?arnumber=11400739 | B14: 10.1109/BigData66926.2025.11400739 | C14: Towards Uncertainty-Aware Low-Bit Quantized LLMs for On-Device Inference | D14: Kaiser | E14: Exclude | F14: Not about Sycophancy
A15: https://doi.org/10.1109/CCGrid.2012.84 | B15: 10.1109/ccgrid.2012.84 | C15: Energy- and Cost-Efficiency Analysis of ARM-Based Clusters | D15: Marilyn | E15: Exclude | F15: Not about either LLMs or Sycophancy
A16: https://doi.org/10.1109/CCGrid.2015.115 | B16: 10.1109/ccgrid.2015.115 | C16: Quantitative musings on the feasibility of smartphone clouds | D16: Jonathan | E16: Exclude | F16: Not about either LLMs or Sycophancy
A17: https://doi.org/10.1109/CCGrid.2015.150 | B17: 10.1109/ccgrid.2015.150 | C17: Deferred lightweight indexing for log-structured key-value stores | D17: Jonathan | E17: Exclude | F17: Not about either LLMs or Sycophancy
A18: https://doi.org/10.1109/CCGRID.2017.49 | B18: 10.1109/ccgrid.2017.49 | C18: High-Performance Key-Value Store On OpenSHMEM | D18: Kaiser | E18: Exclude | F18: Not about either LLMs or Sycophancy
A19: https://ieeexplore.ieee.org/stamp/stamp.jsp?arnumber=1554950 | B19: 10.1109/CEC.2005.1554950 | C19: Learning classifier systems for user context learning | D19: Jonathan | E19: Exclude | F19: Not about either LLMs or Sycophancy
A20: https://ieeexplore.ieee.org/stamp/stamp.jsp?arnumber=11519295 | B20: 10.1109/GAIIS69281.2026.11519295 | C20: PI-Embedding: Scientific Idea Representation Learning via Citation Intent and Paper Provenance | D20: Jonathan | E20: Exclude | F20: Not about Sycophancy
A21: https://ieeexplore.ieee.org/stamp/stamp.jsp?arnumber=10585495 | B21: 10.1109/GEM61861.2024.10585495 | C21: Leveraging Large Language Models for Enhanced VR Development: Insights and Challenges | D21: Marilyn | E21: Exclude | F21: Not about Sycophancy
A22: https://ieeexplore.ieee.org/stamp/stamp.jsp?arnumber=10590666 | B22: 10.1109/HPSC62738.2024.00012 | C22: Studying the Knowledge and Behavior of ChatGPT via Journey to the West | D22: Marilyn | E22: Exclude | F22: Not about Sycophancy
A23: https://ieeexplore.ieee.org/stamp/stamp.jsp?arnumber=11508939 | B23: 10.1109/ICAACE69793.2026.11508939 | C23: Tiny-Critic RAG: Empowering Agentic Fallback with Parameter-Efficient Small Language Models | D23: Jonathan | E23: Exclude | F23: Not about Sycophancy
A24: https://ieeexplore.ieee.org/stamp/stamp.jsp?arnumber=11460702 | B24: 10.1109/ICASSP55912.2026.11460702 | C24: Towards Self-Evaluation of Sycophantic Hallucinations in Mathematical Reasoning | D24: Jonathan | E24: Include
A25: https://ieeexplore.ieee.org/stamp/stamp.jsp?arnumber=11462217 | B25: 10.1109/ICASSP55912.2026.11462217 | C25: FinLumen: A Game-Theoretic Multi-Agent Framework for Rational Portfolio Management | D25: Kaiser | E25: Exclude | F25: Not about Sycophancy
A26: https://ieeexplore.ieee.org/stamp/stamp.jsp?arnumber=5409737 | B26: 10.1109/ICASTECH.2009.5409737 | C26: Tracking a Sycophant Wireless Sensor Network for its seamless integration to mobile Wireless Sensor Networks | D26: Kaiser | E26: Exclude | F26: Not about LLMs
A27: https://ieeexplore.ieee.org/stamp/stamp.jsp?arnumber=6056911 | B27: 10.1109/ICECENG.2011.6056911 | C27: Cohesive subgroups analysis of asynchronous cognitive interactive network in collaborative learning | D27: Jonathan | E27: Exclude | F27: Not about either LLMs or Sycophancy
A28: https://ieeexplore.ieee.org/stamp/stamp.jsp?arnumber=11521627 | B28: 10.1109/ICEIT68991.2026.11521627 | C28: The design of a GAI-supported research topic selection system for novice researchers: From the SECI perspective | D28: Marilyn | E28: Exclude | F28: Not about Sycophancy
A29: https://ieeexplore.ieee.org/stamp/stamp.jsp?arnumber=4299963 | B29: 10.1109/ICSEA.2007.67 | C29: Sycophant: An API for Research in Context-Aware User Interfaces | D29: Jonathan | E29: Exclude | F29: Not about either LLMs or Sycophancy
A30: https://ieeexplore.ieee.org/stamp/stamp.jsp?arnumber=1431446 | B30: 10.1109/IRI.2004.1431446 | C30: Context learning can improve user interaction | D30: Kaiser | E30: Exclude | F30: Not about Sycophancy
A31: https://doi.org/10.1109/ISCA.2016.15 | B31: 10.1109/isca.2016.15 | C31: Morpheus: creating application objects efficiently for heterogeneous computing | D31: Marilyn | E31: Exclude | F31: Not about either LLMs or Sycophancy
A32: https://ieeexplore.ieee.org/stamp/stamp.jsp?arnumber=11269633 | B32: 10.1109/ISTAS65609.2025.11269633 | C32: AI Detection and Risk Estimation in Family Violence: Challenges and Governance | D32: Marilyn | E32: Exclude | F32: Not about either LLMs or Sycophancy
A33: https://ieeexplore.ieee.org/stamp/stamp.jsp?arnumber=4580542 | B33: 10.1109/MIS.2008.55 | C33: A Computational Approach to Etiquette: Operationalizing Brown and Levinson's Politeness Model | D33: Kaiser | E33: Exclude | F33: Not about Sycophancy
A34: https://ieeexplore.ieee.org/stamp/stamp.jsp?arnumber=11345775 | B34: 10.1109/NKCon66957.2025.11345775 | C34: Improving Argumentative Reasoning in LLMs Using Online Debates and Agent-Based Interaction | D34: Jonathan | E34: Exclude | F34: Not about Sycophancy
A35: https://ieeexplore.ieee.org/stamp/stamp.jsp?arnumber=11037824 | B35: 10.1109/OJCS.2025.3580498 | C35: LLMs on a Budget: System-Level Approaches to Power-Efficient and Scalable Fine-Tuning | D35: Kaiser | E35: Exclude | F35: Not about Sycophancy
A36: https://ieeexplore.ieee.org/stamp/stamp.jsp?arnumber=11424465 | B36: 10.1109/RAMS50514.2026.11424465 | C36: Autonomous AI-Driven FMEA Optimization For Safety And Reliability In Healthcare | D36: Marilyn | E36: Exclude | F36: Not about LLMs
A37: https://doi.org/10.1109/SCW63240.2024.00017 | B37: 10.1109/SCW63240.2024.00017 | C37: SciTrust: Evaluating the Trustworthiness of Large Language Models for Science | D37: Jonathan | E37: Exclude | F37: Not about Sycophancy
A38: https://ieeexplore.ieee.org/stamp/stamp.jsp?arnumber=10820709 | B38: 10.1109/SCW63240.2024.00017 | C38: SciTrust: Evaluating the Trustworthiness of Large Language Models for Science | D38: Marilyn | E38: Include
A39: https://ieeexplore.ieee.org/stamp/stamp.jsp?arnumber=11531012 | B39: 10.1109/TDSC.2026.3695553 | C39: MCPXKIT: the Unified Toolkit for Analyzing Model Context Protocol Security | D39: Kaiser | E39: Exclude | F39: Not about Sycophancy
A40: https://ieeexplore.ieee.org/stamp/stamp.jsp?arnumber=5427110 | B40: 10.1109/TEVC.2009.2021466 | C40: XCS for Personalizing Desktop Interfaces | D40: Marilyn | E40: Exclude | F40: Not about either LLMs or Sycophancy
...

Sheet INCEXC B
A1: URL | B1: key | D1: Evaluator Name | E1: Included/Excluded | F1: Excluded Reason | G1: Other
A2: https://doi.org/10.1007/978-3-642-24322-6_15 | B2: 10.1007/978-3-642-24322-6_15 | C2: The search for energy-efficient building blocks for the data center | D2: Taylor | E2: Exclude | F2: Not about either LLMs or Sycophancy
A3: https://doi.org/10.1007/978-3-642-24322-6_16 | B3: 10.1007/978-3-642-24322-6_16 | C3: KnightShift: shifting the I/O burden in datacenters to management processor for energy efficiency | D3: Taylor | E3: Exclude | F3: Not about either LLMs or Sycophancy
A4: https://doi.org/10.1007/978-3-642-24322-6_19 | B4: 10.1007/978-3-642-24322-6_19 | C4: Achieving power-efficiency in clusters without distributed file system complexity | D4: Taylor | E4: Exclude | F4: Not about either LLMs or Sycophancy
A5: https://ieeexplore.ieee.org/stamp/stamp.jsp?arnumber=8372225 | B5: 10.1049/cp.2016.1548 | C5: A SOFC based autonomous microgrid performance analysis using adaptive PI and PI controller | D5: Danni | E5: Exclude | F5: Not about either LLMs or Sycophancy
A6: https://ieeexplore.ieee.org/stamp/stamp.jsp?arnumber=735370 | B6: 10.1109/47.735370 | C6: The letter of submission: avoiding the promotional genre | D6: Ceren | E6: Exclude | F6: Not about either LLMs or Sycophancy
A7: https://ieeexplore.ieee.org/stamp/stamp.jsp?arnumber=11467909 | B7: 10.1109/ACDSA67686.2026.11467909 | C7: Evaluating LLM-Induced Investment Biases via Persona Design and Prompt Analysis: A Quantitative Study of Post-Retirement Asset Depletion Risk Through Social Simulation | D7: Ceren | E7: Include
A8: https://ieeexplore.ieee.org/stamp/stamp.jsp?arnumber=10771051 | B8: 10.1109/AIxSET62544.2024.00047 | C8: Towards Transparent Artificial Intelligence: Exploring Modern Approaches and Future Directions | D8: Danni | E8: Exclude | F8: Not about Sycophancy
A9: https://ieeexplore.ieee.org/stamp/stamp.jsp?arnumber=11449950 | B9: 10.1109/AIxVR67263.2026.00026 | C9: Too Positive to Be True? Sentiment Analysis of AI-Guided vs. Human-Led Debriefings in Virtual Reality Counseling Training | D9: Taylor | E9: Include
A10: https://ieeexplore.ieee.org/stamp/stamp.jsp?arnumber=11334577 | B10: 10.1109/ASE63991.2025.00043 | C10: Why AI Agents Still Need You: Findings from Developer-Agent Collaborations in the Wild | D10: Taylor | E10: Exclude | G10: Touches on it
A11: https://doi.org/10.1109/ASONAM49781.2020.9381292 | B11: 10.1109/asonam49781.2020.9381292 | C11: Aspect based abusive sentiment detection in nepali social media texts | D11: Danni | E11: Exclude | F11: Not about either LLMs or Sycophancy
A12: https://ieeexplore.ieee.org/stamp/stamp.jsp?arnumber=9381292 | B12: 10.1109/ASONAM49781.2020.9381292 | C12: Aspect Based Abusive Sentiment Detection in Nepali Social Media Texts | D12: Taylor | E12: Exclude | F12: Not about either LLMs or Sycophancy
A13: https://ieeexplore.ieee.org/stamp/stamp.jsp?arnumber=10825538 | B13: 10.1109/BigData62323.2024.10825538 | C13: Mitigating Sycophancy in Large Language Models via Direct Preference Optimization | D13: Taylor | E13: Include
A14: https://ieeexplore.ieee.org/stamp/stamp.jsp?arnumber=11400739 | B14: 10.1109/BigData66926.2025.11400739 | C14: Towards Uncertainty-Aware Low-Bit Quantized LLMs for On-Device Inference | D14: Ceren | E14: Exclude | F14: Not about Sycophancy
A15: https://doi.org/10.1109/CCGrid.2012.84 | B15: 10.1109/ccgrid.2012.84 | C15: Energy- and Cost-Efficiency Analysis of ARM-Based Clusters | D15: Ceren | E15: Exclude | F15: Not about either LLMs or Sycophancy
A16: https://doi.org/10.1109/CCGrid.2015.115 | B16: 10.1109/ccgrid.2015.115 | C16: Quantitative musings on the feasibility of smartphone clouds | D16: Taylor | E16: Exclude | F16: Not about either LLMs or Sycophancy
A17: https://doi.org/10.1109/CCGrid.2015.150 | B17: 10.1109/ccgrid.2015.150 | C17: Deferred lightweight indexing for log-structured key-value stores | D17: Danni | E17: Exclude | F17: Not about either LLMs or Sycophancy
A18: https://doi.org/10.1109/CCGRID.2017.49 | B18: 10.1109/ccgrid.2017.49 | C18: High-Performance Key-Value Store On OpenSHMEM | D18: Taylor | E18: Exclude | F18: Not about either LLMs or Sycophancy
A19: https://ieeexplore.ieee.org/stamp/stamp.jsp?arnumber=1554950 | B19: 10.1109/CEC.2005.1554950 | C19: Learning classifier systems for user context learning | D19: Taylor | E19: Exclude | F19: Not about either LLMs or Sycophancy
A20: https://ieeexplore.ieee.org/stamp/stamp.jsp?arnumber=11519295 | B20: 10.1109/GAIIS69281.2026.11519295 | C20: PI-Embedding: Scientific Idea Representation Learning via Citation Intent and Paper Provenance | D20: Ceren | E20: Exclude | F20: Not about Sycophancy
A21: https://ieeexplore.ieee.org/stamp/stamp.jsp?arnumber=10585495 | B21: 10.1109/GEM61861.2024.10585495 | C21: Leveraging Large Language Models for Enhanced VR Development: Insights and Challenges | D21: Taylor | E21: Exclude | F21: Not about Sycophancy
A22: https://ieeexplore.ieee.org/stamp/stamp.jsp?arnumber=10590666 | B22: 10.1109/HPSC62738.2024.00012 | C22: Studying the Knowledge and Behavior of ChatGPT via Journey to the West | D22: Ceren | E22: Exclude | F22: Not about Sycophancy
A23: https://ieeexplore.ieee.org/stamp/stamp.jsp?arnumber=11508939 | B23: 10.1109/ICAACE69793.2026.11508939 | C23: Tiny-Critic RAG: Empowering Agentic Fallback with Parameter-Efficient Small Language Models | D23: Taylor | E23: Exclude | F23: Not about Sycophancy
A24: https://ieeexplore.ieee.org/stamp/stamp.jsp?arnumber=11460702 | B24: 10.1109/ICASSP55912.2026.11460702 | C24: Towards Self-Evaluation of Sycophantic Hallucinations in Mathematical Reasoning | D24: Danni | E24: Include
A25: https://ieeexplore.ieee.org/stamp/stamp.jsp?arnumber=11462217 | B25: 10.1109/ICASSP55912.2026.11462217 | C25: FinLumen: A Game-Theoretic Multi-Agent Framework for Rational Portfolio Management | D25: Ceren | E25: Exclude | F25: Not about Sycophancy
A26: https://ieeexplore.ieee.org/stamp/stamp.jsp?arnumber=5409737 | B26: 10.1109/ICASTECH.2009.5409737 | C26: Tracking a Sycophant Wireless Sensor Network for its seamless integration to mobile Wireless Sensor Networks | D26: Danni | E26: Exclude | F26: Not about either LLMs or Sycophancy
A27: https://ieeexplore.ieee.org/stamp/stamp.jsp?arnumber=6056911 | B27: 10.1109/ICECENG.2011.6056911 | C27: Cohesive subgroups analysis of asynchronous cognitive interactive network in collaborative learning | D27: Danni | E27: Exclude | F27: Not about either LLMs or Sycophancy
A28: https://ieeexplore.ieee.org/stamp/stamp.jsp?arnumber=11521627 | B28: 10.1109/ICEIT68991.2026.11521627 | C28: The design of a GAI-supported research topic selection system for novice researchers: From the SECI perspective | D28: Danni | E28: Exclude | F28: Not about Sycophancy
A29: https://ieeexplore.ieee.org/stamp/stamp.jsp?arnumber=4299963 | B29: 10.1109/ICSEA.2007.67 | C29: Sycophant: An API for Research in Context-Aware User Interfaces | D29: Danni | E29: Exclude | F29: Not about either LLMs or Sycophancy
A30: https://ieeexplore.ieee.org/stamp/stamp.jsp?arnumber=1431446 | B30: 10.1109/IRI.2004.1431446 | C30: Context learning can improve user interaction | D30: Danni | E30: Exclude | F30: Other (Explanation ->) | G30: Page not found
A31: https://doi.org/10.1109/ISCA.2016.15 | B31: 10.1109/isca.2016.15 | C31: Morpheus: creating application objects efficiently for heterogeneous computing | D31: Danni | E31: Exclude | F31: Not about either LLMs or Sycophancy
A32: https://ieeexplore.ieee.org/stamp/stamp.jsp?arnumber=11269633 | B32: 10.1109/ISTAS65609.2025.11269633 | C32: AI Detection and Risk Estimation in Family Violence: Challenges and Governance | D32: Danni | E32: Exclude | F32: Not about Sycophancy
A33: https://ieeexplore.ieee.org/stamp/stamp.jsp?arnumber=4580542 | B33: 10.1109/MIS.2008.55 | C33: A Computational Approach to Etiquette: Operationalizing Brown and Levinson's Politeness Model | D33: Danni | E33: Exclude | F33: Not about either LLMs or Sycophancy
A34: https://ieeexplore.ieee.org/stamp/stamp.jsp?arnumber=11345775 | B34: 10.1109/NKCon66957.2025.11345775 | C34: Improving Argumentative Reasoning in LLMs Using Online Debates and Agent-Based Interaction | D34: Danni | E34: Exclude | F34: Not about Sycophancy
A35: https://ieeexplore.ieee.org/stamp/stamp.jsp?arnumber=11037824 | B35: 10.1109/OJCS.2025.3580498 | C35: LLMs on a Budget: System-Level Approaches to Power-Efficient and Scalable Fine-Tuning | D35: Ceren | E35: Exclude | F35: Not about Sycophancy
A36: https://ieeexplore.ieee.org/stamp/stamp.jsp?arnumber=11424465 | B36: 10.1109/RAMS50514.2026.11424465 | C36: Autonomous AI-Driven FMEA Optimization For Safety And Reliability In Healthcare | D36: Taylor | E36: Include
A37: https://doi.org/10.1109/SCW63240.2024.00017 | B37: 10.1109/SCW63240.2024.00017 | C37: SciTrust: Evaluating the Trustworthiness of Large Language Models for Science | D37: Danni | E37: Exclude | F37: Not about Sycophancy
A38: https://ieeexplore.ieee.org/stamp/stamp.jsp?arnumber=10820709 | B38: 10.1109/SCW63240.2024.00017 | C38: SciTrust: Evaluating the Trustworthiness of Large Language Models for Science | D38: Ceren | E38: Include
A39: https://ieeexplore.ieee.org/stamp/stamp.jsp?arnumber=11531012 | B39: 10.1109/TDSC.2026.3695553 | C39: MCPXKIT: the Unified Toolkit for Analyzing Model Context Protocol Security | D39: Ceren | E39: Exclude | F39: Not about Sycophancy
A40: https://ieeexplore.ieee.org/stamp/stamp.jsp?arnumber=5427110 | B40: 10.1109/TEVC.2009.2021466 | C40: XCS for Personalizing Desktop Interfaces | D40: Ceren | E40: Exclude | F40: Not about either LLMs or Sycophancy
...

Sheet Query Validation
A1: Check | B1: Evaluator | C1: Sycophantic Papers? | D1: Title 1 | E1: Title 2 | F1: In All Papers | G1: Included in INC/EXC Disc
A2: SESSION: AI & Data Visualization | B2: Tina | C2: No
A3: SESSION: AI & Timing Matters | B3: Tina | C3: No
A4: SESSION: AI Collaboration in Practice | B4: Tina | C4: No
A5: SESSION: AI Explanations and Decision Support in Healthcare | B5: Tina | C5: No
A6: SESSION: AI Governance and Accountability | B6: Tina | C6: No
A7: SESSION: AI Governance and Safety | B7: Tina | C7: No
A8: SESSION: AI Literacy, Ethics, and Critical AI Understanding | B8: Tina | C8: No
A9: SESSION: AI Personality | B9: Tina | C9: No
A10: SESSION: AI Risks | B10: Tina | C10: No
A11: SESSION: AI Systems for Human Goals | B11: Tina | C11: No
A12: SESSION: AI Tutors and Learning Support Systems | B12: Tina | C12: No
A13: SESSION: AI for Language Learning & Communication Skills | B13: Tina | C13: No
... A17: SESSION: AI in Family, Dating and Private Life | B17: Tina | C17: No
A18: SESSION: AI in Practice | B18: Tina | C18: Yes | D18: Personal Validation Effect in LLMs: Positive AI Responses Bias Perceptions of Validity, Reliability, Personalization, and Usefulness of Fictitious Predictions | F18: Yes | G18: Yes
A19: SESSION: AI in Work and Expertise | B19: Tina | C19: No
A20: SESSION: AI, Learning and Inclusion in Education | B20: Tina | C20: No
A21: SESSION: AI, Motivation and Learning | B21: Tina | C21: No
A22: SESSION: AI-Assisted Clinical Diagnosis and Reasoning | B22: Tina | C22: No
A23: SESSION: AI-Driven Creativity & Design Methods | B23: Tina | C23: No
A24: SESSION: Accessibility in Everyday Life | B24: Tina | C24: No
A25: SESSION: Affective Agents & Reflective Data | B25: Tina | C25: No
A26: SESSION: Aging and Later Life | B26: Tina | C26: No
A27: SESSION: Algorithmic Power, Justice and Repression | B27: Tina | C27: No
A28: SESSION: Alternative Perspectives | B28: Tina | C28: No
A29: SESSION: Animals & Nature | B29: Tina | C29: No
A30: SESSION: Assistive Tech and Professional Inclusion | B30: Tina | C30: No
... A54: SESSION: Conversational AI | B54: Tina | C54: No
A55: SESSION: Conversational AI, Agency and Control | B55: Tina | C55: Yes | D55: Polite But Boring? Trade-offs Between Engagement and Psychological Reactance to Chatbot Feedback Styles | F55: Yes | G55: No
A56: SESSION: Creating with AI | B56: Tina | C56: No
A57: SESSION: Creativity and Innovation | B57: Tina | C57: No
A58: SESSION: Critical Reflections on AI | B58: Tina | C58: No
A59: SESSION: Dark Patterns, Deception, and Manipulative Interfaces | B59: Tina | C59: No
A60: SESSION: Data Visualization Designs and Tools | B60: Tina | C60: No
A61: SESSION: Data Work | B61: Tina | C61: No
A62: SESSION: Design Methods and Frameworks | B62: Tina | C62: No
A63: SESSION: Designing Care Futures | B63: Tina | C63: No
A64: SESSION: Designing Creative GenAI Tools | B64: Tina | C64: No
A65: SESSION: Designing Data Visualizations | B65: Tina | C65: No
A66: SESSION: Designing Player Experience | B66: Tina | C66: No
...

Sheet INCEXC Disc
C1: Matching | D1: Key | E1: Title | F1: Coder A | G1: Coder B | H1: Code A | I1: Code B | J1: Match | K1: Agreed include
A2: ='INCEXC A'!A2 -> https://doi.org/10.1007/978-3-642-24322-6_15 | B2: ='INCEXC B'!A2 -> https://doi.org/10.1007/978-3-642-24322-6_15 | C2: =A2=B2 -> TRUE | D2: ='INCEXC A'!B2 -> 10.1007/978-3-642-24322-6_15 | E2: ='INCEXC A'!C2 -> The search for energy-efficient building blocks for the data center | F2: ='INCEXC A'!D2 -> Jonathan | G2: ='INCEXC B'!D2 -> Taylor | H2: ='INCEXC A'!E2 -> Exclude | I2: ='INCEXC B'!E2 -> Exclude | J2: =H2=I2 -> TRUE | K2: =AND(H2="Include",J2) -> FALSE
A3: ='INCEXC A'!A3 -> https://doi.org/10.1007/978-3-642-24322-6_16 | B3: ='INCEXC B'!A3 -> https://doi.org/10.1007/978-3-642-24322-6_16 | C3: =A3=B3 -> TRUE | D3: ='INCEXC A'!B3 -> 10.1007/978-3-642-24322-6_16 | E3: ='INCEXC A'!C3 -> KnightShift: shifting the I/O burden in datacenters to management processor for energy efficiency | F3: ='INCEXC A'!D3 -> Marilyn | G3: ='INCEXC B'!D3 -> Taylor | H3: ='INCEXC A'!E3 -> Exclude | I3: ='INCEXC B'!E3 -> Exclude | J3: =H3=I3 -> TRUE | K3: =AND(H3="Include",J3) -> FALSE | L3: ='INCEXC A'!L3 | M3: ='INCEXC B'!L3 | O3: ='INCEXC A'!M3 | P3: ='INCEXC A'!N3 | Q3: ='INCEXC A'!O3 | R3: ='INCEXC B'!O3 | S3: ='INCEXC A'!P3 | T3: ='INCEXC B'!P3 | U3: =S3=T3 -> TRUE | V3: =AND(S3="Include",U3) -> FALSE
A4: ='INCEXC A'!A4 -> https://doi.org/10.1007/978-3-642-24322-6_19 | B4: ='INCEXC B'!A4 -> https://doi.org/10.1007/978-3-642-24322-6_19 | C4: =A4=B4 -> TRUE | D4: ='INCEXC A'!B4 -> 10.1007/978-3-642-24322-6_19 | E4: ='INCEXC A'!C4 -> Achieving power-efficiency in clusters without distributed file system complexity | F4: ='INCEXC A'!D4 -> Marilyn | G4: ='INCEXC B'!D4 -> Taylor | H4: ='INCEXC A'!E4 -> Exclude | I4: ='INCEXC B'!E4 -> Exclude | J4: =H4=I4 -> TRUE | K4: =AND(H4="Include",J4) -> FALSE | L4: ='INCEXC A'!L4 | M4: ='INCEXC B'!L4 | O4: ='INCEXC A'!M4 | P4: ='INCEXC A'!N4 | Q4: ='INCEXC A'!O4 | R4: ='INCEXC B'!O4 | S4: ='INCEXC A'!P4 | T4: ='INCEXC B'!P4 | U4: =S4=T4 -> TRUE | V4: =AND(S4="Include",U4) -> FALSE
A5: ='INCEXC A'!A5 -> https://ieeexplore.ieee.org/stamp/stamp.jsp?arnumber=8372225 | B5: ='INCEXC B'!A5 -> https://ieeexplore.ieee.org/stamp/stamp.jsp?arnumber=8372225 | C5: =A5=B5 -> TRUE | D5: ='INCEXC A'!B5 -> 10.1049/cp.2016.1548 | E5: ='INCEXC A'!C5 -> A SOFC based autonomous microgrid performance analysis using adaptive PI and PI controller | F5: ='INCEXC A'!D5 -> Marilyn | G5: ='INCEXC B'!D5 -> Danni | H5: ='INCEXC A'!E5 -> Exclude | I5: ='INCEXC B'!E5 -> Exclude | J5: =H5=I5 -> TRUE | K5: =AND(H5="Include",J5) -> FALSE | L5: ='INCEXC A'!L5 | M5: ='INCEXC B'!L5 | O5: ='INCEXC A'!M5 | P5: ='INCEXC A'!N5 | Q5: ='INCEXC A'!O5 | R5: ='INCEXC B'!O5 | S5: ='INCEXC A'!P5 | T5: ='INCEXC B'!P5 | U5: =S5=T5 -> TRUE | V5: =AND(S5="Include",U5) -> FALSE
A6: ='INCEXC A'!A6 -> https://ieeexplore.ieee.org/stamp/stamp.jsp?arnumber=735370 | B6: ='INCEXC B'!A6 -> https://ieeexplore.ieee.org/stamp/stamp.jsp?arnumber=735370 | C6: =A6=B6 -> TRUE | D6: ='INCEXC A'!B6 -> 10.1109/47.735370 | E6: ='INCEXC A'!C6 -> The letter of submission: avoiding the promotional genre | F6: ='INCEXC A'!D6 -> Jonathan | G6: ='INCEXC B'!D6 -> Ceren | H6: ='INCEXC A'!E6 -> Exclude | I6: ='INCEXC B'!E6 -> Exclude | J6: =H6=I6 -> TRUE | K6: =AND(H6="Include",J6) -> FALSE | L6: ='INCEXC A'!L6 | M6: ='INCEXC B'!L6 | O6: ='INCEXC A'!M6 | P6: ='INCEXC A'!N6 | Q6: ='INCEXC A'!O6 | R6: ='INCEXC B'!O6 | S6: ='INCEXC A'!P6 | T6: ='INCEXC B'!P6 | U6: =S6=T6 -> TRUE | V6: =AND(S6="Include",U6) -> FALSE
A7: ='INCEXC A'!A7 -> https://ieeexplore.ieee.org/stamp/stamp.jsp?arnumber=11467909 | B7: ='INCEXC B'!A7 -> https://ieeexplore.ieee.org/stamp/stamp.jsp?arnumber=11467909 | C7: =A7=B7 -> TRUE | D7: ='INCEXC A'!B7 -> 10.1109/ACDSA67686.2026.11467909 | E7: ='INCEXC A'!C7 -> Evaluating LLM-Induced Investment Biases via Persona Design and Prompt Analysis: A Quantitative Study of Post-Retirement Asset Depletion Risk Through Social Simulation | F7: ='INCEXC A'!D7 -> Marilyn | G7: ='INCEXC B'!D7 -> Ceren | H7: ='INCEXC A'!E7 -> Include | I7: ='INCEXC B'!E7 -> Include | J7: =H7=I7 -> TRUE | K7: =AND(H7="Include",J7) -> TRUE | L7: ='INCEXC A'!L7 | M7: ='INCEXC B'!L7 | O7: ='INCEXC A'!M7 | P7: ='INCEXC A'!N7 | Q7: ='INCEXC A'!O7 | R7: ='INCEXC B'!O7 | S7: ='INCEXC A'!P7 | T7: ='INCEXC B'!P7 | U7: =S7=T7 -> TRUE | V7: =AND(S7="Include",U7) -> FALSE
A8: ='INCEXC A'!A8 -> https://ieeexplore.ieee.org/stamp/stamp.jsp?arnumber=10771051 | B8: ='INCEXC B'!A8 -> https://ieeexplore.ieee.org/stamp/stamp.jsp?arnumber=10771051 | C8: =A8=B8 -> TRUE | D8: ='INCEXC A'!B8 -> 10.1109/AIxSET62544.2024.00047 | E8: ='INCEXC A'!C8 -> Towards Transparent Artificial Intelligence: Exploring Modern Approaches and Future Directions | F8: ='INCEXC A'!D8 -> Kaiser | G8: ='INCEXC B'!D8 -> Danni | H8: ='INCEXC A'!E8 -> Exclude | I8: ='INCEXC B'!E8 -> Exclude | J8: =H8=I8 -> TRUE | K8: =AND(H8="Include",J8) -> FALSE | L8: ='INCEXC A'!L8 | M8: ='INCEXC B'!L8 | O8: ='INCEXC A'!M8 | P8: ='INCEXC A'!N8 | Q8: ='INCEXC A'!O8 | R8: ='INCEXC B'!O8 | S8: ='INCEXC A'!P8 | T8: ='INCEXC B'!P8 | U8: =S8=T8 -> TRUE | V8: =AND(S8="Include",U8) -> FALSE
A9: ='INCEXC A'!A9 -> https://ieeexplore.ieee.org/stamp/stamp.jsp?arnumber=11449950 | B9: ='INCEXC B'!A9 -> https://ieeexplore.ieee.org/stamp/stamp.jsp?arnumber=11449950 | C9: =A9=B9 -> TRUE | D9: ='INCEXC A'!B9 -> 10.1109/AIxVR67263.2026.00026 | E9: ='INCEXC A'!C9 -> Too Positive to Be True? Sentiment Analysis of AI-Guided vs. Human-Led Debriefings in Virtual Reality Counseling Training | F9: ='INCEXC A'!D9 -> Kaiser | G9: ='INCEXC B'!D9 -> Taylor | H9: ='INCEXC A'!E9 -> Include | I9: ='INCEXC B'!E9 -> Include | J9: =H9=I9 -> TRUE | K9: =AND(H9="Include",J9) -> TRUE | L9: ='INCEXC A'!L9 | M9: ='INCEXC B'!L9 | O9: ='INCEXC A'!M9 | P9: ='INCEXC A'!N9 | Q9: ='INCEXC A'!O9 | R9: ='INCEXC B'!O9 | S9: ='INCEXC A'!P9 | T9: ='INCEXC B'!P9 | U9: =S9=T9 -> TRUE | V9: =AND(S9="Include",U9) -> FALSE
A10: ='INCEXC A'!A10 -> https://ieeexplore.ieee.org/stamp/stamp.jsp?arnumber=11334577 | B10: ='INCEXC B'!A10 -> https://ieeexplore.ieee.org/stamp/stamp.jsp?arnumber=11334577 | C10: =A10=B10 -> TRUE | D10: ='INCEXC A'!B10 -> 10.1109/ASE63991.2025.00043 | E10: ='INCEXC A'!C10 -> Why AI Agents Still Need You: Findings from Developer-Agent Collaborations in the Wild | F10: ='INCEXC A'!D10 -> Kaiser | G10: ='INCEXC B'!D10 -> Taylor | H10: ='INCEXC A'!E10 -> Exclude | I10: ='INCEXC B'!E10 -> Exclude | J10: =H10=I10 -> TRUE | K10: =AND(H10="Include",J10) -> FALSE | L10: ='INCEXC A'!L10 | M10: ='INCEXC B'!L10 | O10: ='INCEXC A'!M10 | P10: ='INCEXC A'!N10 | Q10: ='INCEXC A'!O10 | R10: ='INCEXC B'!O10 | S10: ='INCEXC A'!P10 | T10: ='INCEXC B'!P10 | U10: =S10=T10 -> TRUE | V10: =AND(S10="Include",U10) -> FALSE
A11: ='INCEXC A'!A11 -> https://ieeexplore.ieee.org/stamp/stamp.jsp?arnumber=9381292 | B11: ='INCEXC B'!A11 -> https://doi.org/10.1109/ASONAM49781.2020.9381292 | C11: =A11=B11 -> FALSE | D11: ='INCEXC A'!B11 -> 10.1109/ASONAM49781.2020.9381292 | E11: ='INCEXC A'!C11 -> Aspect Based Abusive Sentiment Detection in Nepali Social Media Texts | F11: ='INCEXC A'!D11 -> Jonathan | G11: ='INCEXC B'!D11 -> Danni | H11: ='INCEXC A'!E11 -> Exclude | I11: ='INCEXC B'!E11 -> Exclude | J11: =H11=I11 -> TRUE | K11: =AND(H11="Include",J11) -> FALSE | L11: ='INCEXC A'!L11 | M11: ='INCEXC B'!L11 | O11: ='INCEXC A'!M11 | P11: ='INCEXC A'!N11 | Q11: ='INCEXC A'!O11 | R11: ='INCEXC B'!O11 | S11: ='INCEXC A'!P11 | T11: ='INCEXC B'!P11 | U11: =S11=T11 -> TRUE | V11: =AND(S11="Include",U11) -> FALSE
A12: ='INCEXC A'!A12 -> https://doi.org/10.1109/ASONAM49781.2020.9381292 | B12: ='INCEXC B'!A12 -> https://ieeexplore.ieee.org/stamp/stamp.jsp?arnumber=9381292 | C12: =A12=B12 -> FALSE | D12: ='INCEXC A'!B12 -> 10.1109/asonam49781.2020.9381292 | E12: ='INCEXC A'!C12 -> Aspect based abusive sentiment detection in nepali social media texts | F12: ='INCEXC A'!D12 -> Marilyn | G12: ='INCEXC B'!D12 -> Taylor | H12: ='INCEXC A'!E12 -> Exclude | I12: ='INCEXC B'!E12 -> Exclude | J12: =H12=I12 -> TRUE | K12: =AND(H12="Include",J12) -> FALSE | L12: ='INCEXC A'!L12 | M12: ='INCEXC B'!L12 | O12: ='INCEXC A'!M12 | P12: ='INCEXC A'!N12 | Q12: ='INCEXC A'!O12 | R12: ='INCEXC B'!O12 | S12: ='INCEXC A'!P12 | T12: ='INCEXC B'!P12 | U12: =S12=T12 -> TRUE | V12: =AND(S12="Include",U12) -> FALSE
A13: ='INCEXC A'!A13 -> https://ieeexplore.ieee.org/stamp/stamp.jsp?arnumber=10825538 | B13: ='INCEXC B'!A13 -> https://ieeexplore.ieee.org/stamp/stamp.jsp?arnumber=10825538 | C13: =A13=B13 -> TRUE | D13: ='INCEXC A'!B13 -> 10.1109/BigData62323.2024.10825538 | E13: ='INCEXC A'!C13 -> Mitigating Sycophancy in Large Language Models via Direct Preference Optimization | F13: ='INCEXC A'!D13 -> Kaiser | G13: ='INCEXC B'!D13 -> Taylor | H13: ='INCEXC A'!E13 -> Include | I13: ='INCEXC B'!E13 -> Include | J13: =H13=I13 -> TRUE | K13: =AND(H13="Include",J13) -> TRUE | L13: ='INCEXC A'!L13 | M13: ='INCEXC B'!L13 | O13: ='INCEXC A'!M13 | P13: ='INCEXC A'!N13 | Q13: ='INCEXC A'!O13 | R13: ='INCEXC B'!O13 | S13: ='INCEXC A'!P13 | T13: ='INCEXC B'!P13 | U13: =S13=T13 -> TRUE | V13: =AND(S13="Include",U13) -> FALSE
A14: ='INCEXC A'!A14 -> https://ieeexplore.ieee.org/stamp/stamp.jsp?arnumber=11400739 | B14: ='INCEXC B'!A14 -> https://ieeexplore.ieee.org/stamp/stamp.jsp?arnumber=11400739 | C14: =A14=B14 -> TRUE | D14: ='INCEXC A'!B14 -> 10.1109/BigData66926.2025.11400739 | E14: ='INCEXC A'!C14 -> Towards Uncertainty-Aware Low-Bit Quantized LLMs for On-Device Inference | F14: ='INCEXC A'!D14 -> Kaiser | G14: ='INCEXC B'!D14 -> Ceren | H14: ='INCEXC A'!E14 -> Exclude | I14: ='INCEXC B'!E14 -> Exclude | J14: =H14=I14 -> TRUE | K14: =AND(H14="Include",J14) -> FALSE | L14: ='INCEXC A'!L14 | M14: ='INCEXC B'!L14 | O14: ='INCEXC A'!M14 | P14: ='INCEXC A'!N14 | Q14: ='INCEXC A'!O14 | R14: ='INCEXC B'!O14 | S14: ='INCEXC A'!P14 | T14: ='INCEXC B'!P14 | U14: =S14=T14 -> TRUE | V14: =AND(S14="Include",U14) -> FALSE
... A396: ='INCEXC A'!A396 -> https://ieeexplore.ieee.org/stamp/stamp.jsp?arnumber=6921105 | B396: ='INCEXC B'!A396 -> https://ieeexplore.ieee.org/xpl/ebooks/bookPdfWithBanner.jsp?fileName=8646901.pdf&bkn=8646803&pdfType=chapter | C396: =A396=B396 -> FALSE | D396: ='INCEXC A'!B396 -> X | E396: ='INCEXC A'!C396 -> Exploring the national role and position of international technology diffusion: A technological embeddedness perspective | F396: ='INCEXC A'!D396 -> Kaiser | G396: ='INCEXC B'!D396 -> Taylor | H396: ='INCEXC A'!E396 -> Exclude | I396: ='INCEXC B'!E396 -> Exclude | J396: =H396=I396 -> TRUE | K396: =AND(H396="Include",J396) -> FALSE | L396: ='INCEXC A'!L396 | M396: ='INCEXC B'!L396 | O396: ='INCEXC A'!M396 | P396: ='INCEXC A'!N396 | Q396: ='INCEXC A'!O396 | R396: ='INCEXC B'!O396 | S396: ='INCEXC A'!P396 | T396: ='INCEXC B'!P396 | U396: =S396=T396 -> TRUE | V396: =AND(S396="Include",U396) -> FALSE

Sheet Mapping A
A1: URL | B1: Key | C1: Title | D1: Coder | E1: Mapped | F1: Population (Whos is doing the judging of sycophancy?) | K1: Definition of Sycophancy (what exactly do they mean by sycophancy) | P1: Outcomes (Are they measuring the impact of sycophancy on something else?)
E2: At least one X in each category | F2: Human - general | G2: Human - Student | H2: Human - Specialist | I2: Human - Authors | J2: AI - prompted | K2: Hallucination Agreement | L2: Bias Agreement | M2: Obsequiousness | N2: Stance Change | O2: Failure to challenge/trying to get along | P2: None | Q2: User opinion | R2: User action | S2: System performance | T2: User performance
F3: A human judge with no specific expertise | G3: Specifically having students judge | H3: Having someone with expertise (psychologist, conversation expert, etc) judge | I3: Authors judging | J3: Some sort of prompted AI doing the judging | K3: Saying something objectively wrong/harmful becuase the user wants it to be so | L3: The LLM choosing something that isn't objectively wrong, but siding towards the version that it believes user would want | M3: Fawning or overly positive language | N3: Getting the LLM to change opinions/stance/viewpoint to please/mirror user | O3: LLM failing to push back or challenge user or just going along with user's suggestion despite potential problems | P3: Just measuing sycophancy directly with no impact | Q3: Measuring how users feel/react in some way | R3: Measuring something about how users behave while/after interacting with sycophantic LLMS | S3: Some measure of how sycophantic LLMs perform on some task | T3: Some measure of how well the user is able to accomplish a task with sycophantic/non-sycophantic agents
A4: https://ieeexplore.ieee.org/stamp/stamp.jsp?arnumber=11467909 | B4: 10.1109/ACDSA67686.2026.11467909 | C4: Evaluating LLM-Induced Investment Biases via Persona Design and Prompt Analysis: A Quantitative Study of Post-Retirement Asset Depletion Risk Through Social Simulation | D4: Ceren | E4: =IF(AND(COUNTIF(F4:J4,"X")>0,COUNTIF(K4:O4,"X")>0,COUNTIF(P4:T4,"X")>0),"X","")
A5: https://ieeexplore.ieee.org/stamp/stamp.jsp?arnumber=11449950 | B5: 10.1109/AIxVR67263.2026.00026 | C5: Too Positive to Be True? Sentiment Analysis of AI-Guided vs. Human-Led Debriefings in Virtual Reality Counseling Training | D5: Ceren | E5: =IF(AND(COUNTIF(F5:J5,"X")>0,COUNTIF(K5:O5,"X")>0,COUNTIF(P5:T5,"X")>0),"X","") -> X | J5: X | M5: X | O5: X | R5: X
A6: https://ieeexplore.ieee.org/stamp/stamp.jsp?arnumber=10825538 | B6: 10.1109/BigData62323.2024.10825538 | C6: Mitigating Sycophancy in Large Language Models via Direct Preference Optimization | D6: Ceren | E6: =IF(AND(COUNTIF(F6:J6,"X")>0,COUNTIF(K6:O6,"X")>0,COUNTIF(P6:T6,"X")>0),"X","") -> X | J6: X | N6: X | O6: X | S6: X
A7: https://ieeexplore.ieee.org/stamp/stamp.jsp?arnumber=11460702 | B7: 10.1109/ICASSP55912.2026.11460702 | C7: Towards Self-Evaluation of Sycophantic Hallucinations in Mathematical Reasoning | D7: Ceren | E7: =IF(AND(COUNTIF(F7:J7,"X")>0,COUNTIF(K7:O7,"X")>0,COUNTIF(P7:T7,"X")>0),"X","") -> X | J7: X | K7: X | N7: X | O7: X | S7: X
A8: https://ieeexplore.ieee.org/stamp/stamp.jsp?arnumber=11424465 | B8: 10.1109/RAMS50514.2026.11424465 | C8: Autonomous AI-Driven FMEA Optimization For Safety And Reliability In Healthcare | D8: Ceren | E8: =IF(AND(COUNTIF(F8:J8,"X")>0,COUNTIF(K8:O8,"X")>0,COUNTIF(P8:T8,"X")>0),"X","")
A9: https://ieeexplore.ieee.org/stamp/stamp.jsp?arnumber=10820709 | B9: 10.1109/SCW63240.2024.00017 | C9: SciTrust: Evaluating the Trustworthiness of Large Language Models for Science | D9: Ceren | E9: =IF(AND(COUNTIF(F9:J9,"X")>0,COUNTIF(K9:O9,"X")>0,COUNTIF(P9:T9,"X")>0),"X","") -> X | I9: X | J9: X | K9: X | S9: X
A10: https://doi.org/10.1145/1518701.1519021 | B10: 10.1145/1518701.1519021 | C10: I'm sorry | D10: Ceren | E10: =IF(AND(COUNTIF(F10:J10,"X")>0,COUNTIF(K10:O10,"X")>0,COUNTIF(P10:T10,"X")>0),"X","") -> X | F10: X | O10: X | Q10: X | R10: X
A11: https://doi.org/10.1145/3660650.3660656 | B11: 10.1145/3660650.3660656 | C11: Faceless Adversary | D11: Cindy | E11: =IF(AND(COUNTIF(F11:J11,"X")>0,COUNTIF(K11:O11,"X")>0,COUNTIF(P11:T11,"X")>0),"X","") -> X | H11: X | M11: X | O11: X | P11: X
A12: https://doi.org/10.1145/3663547.3746319 | B12: 10.1145/3663547.3746319 | C12: Probing the Gaps in ChatGPT's Live Video Chat for Real-World Assistance for People who are Blind or Visually Impaired | D12: Cindy | E12: =IF(AND(COUNTIF(F12:J12,"X")>0,COUNTIF(K12:O12,"X")>0,COUNTIF(P12:T12,"X")>0),"X","") -> X | I12: X | O12: X | Q12: X | R12: X
A13: https://doi.org/10.1145/3703155 | B13: 10.1145/3703155 | C13: A Survey on Hallucination in Large Language Models: Principles | D13: Cindy | E13: =IF(AND(COUNTIF(F13:J13,"X")>0,COUNTIF(K13:O13,"X")>0,COUNTIF(P13:T13,"X")>0),"X","") -> X | H13: X | K13: X | O13: X | S13: X
A14: https://doi.org/10.1145/3706599.3719976 | B14: 10.1145/3706599.3719976 | C14: Exploring Older Adults Personality Preferences for LLM-powered Conversational Companions | D14: Cindy | E14: =IF(AND(COUNTIF(F14:J14,"X")>0,COUNTIF(K14:O14,"X")>0,COUNTIF(P14:T14,"X")>0),"X","") -> X | F14: X | L14: X | O14: X | Q14: X
A15: https://doi.org/10.1145/3715275.3732039 | B15: 10.1145/3715275.3732039 | C15: Expressing stigma and inappropriate responses prevents LLMs from safely replacing mental health providers. | D15: Cindy | E15: =IF(AND(COUNTIF(F15:J15,"X")>0,COUNTIF(K15:O15,"X")>0,COUNTIF(P15:T15,"X")>0),"X","") -> X | H15: X | J15: X | O15: X | S15: X
A16: https://doi.org/10.1145/3717511.3747073 | B16: 10.1145/3717511.3747073 | C16: Interactive Social Agent Behaviors of Politeness and Compromise in Collaborative Decision-making | D16: Cindy | E16: =IF(AND(COUNTIF(F16:J16,"X")>0,COUNTIF(K16:O16,"X")>0,COUNTIF(P16:T16,"X")>0),"X","") -> X | F16: X | L16: X | O16: X | T16: X
A17: https://doi.org/10.1145/3719160.3736618 | B17: 10.1145/3719160.3736618 | C17: Navigating the Fog: How University Students Recalibrate Sensemaking Practices to Address Plausible Falsehoods in LLM Outputs | D17: Cindy | E17: =IF(AND(COUNTIF(F17:J17,"X")>0,COUNTIF(K17:O17,"X")>0,COUNTIF(P17:T17,"X")>0),"X","") -> X | G17: X | N17: X | Q17: X | R17: X
A18: https://doi.org/10.1145/3742413.3789120 | B18: 10.1145/3742413.3789120 | C18: Neural Transparency: Mechanistic Interpretability Interfaces for Anticipating Model Behaviors for Personalized AI | D18: Danni | E18: =IF(AND(COUNTIF(F18:J18,"X")>0,COUNTIF(K18:O18,"X")>0,COUNTIF(P18:T18,"X")>0),"X","") -> X | F18: X | J18: X | O18: X | R18: X | T18: X
A19: https://doi.org/10.1145/3744169.3744194 | B19: 10.1145/3744169.3744194 | C19: Reading the Praise/Prompt Machine: An Interface Criticism Approach to ChatGPT | D19: Danni | E19: =IF(AND(COUNTIF(F19:J19,"X")>0,COUNTIF(K19:O19,"X")>0,COUNTIF(P19:T19,"X")>0),"X","") -> X | I19: X | M19: X | O19: X | P19: X
A20: https://doi.org/10.1145/3746027.3755778 | B20: 10.1145/3746027.3755778 | C20: Evaluating and Mitigating Sycophancy in Large Vision-Language Models | D20: Danni | E20: =IF(AND(COUNTIF(F20:J20,"X")>0,COUNTIF(K20:O20,"X")>0,COUNTIF(P20:T20,"X")>0),"X","") -> X | I20: X | K20: X | N20: X | S20: X
A21: https://doi.org/10.1145/3772318.3790332 | B21: 10.1145/3772318.3790332 | C21: Behavioral Indicators of Overreliance During Interaction with Conversational Language Models | D21: Danni | E21: =IF(AND(COUNTIF(F21:J21,"X")>0,COUNTIF(K21:O21,"X")>0,COUNTIF(P21:T21,"X")>0),"X","") -> X | G21: X | K21: X | R21: X | T21: X
A22: https://doi.org/10.1145/3772318.3790385 | B22: 10.1145/3772318.3790385 | C22: Understanding Compliance and Conversion Dynamics in Multi-Agent Collectives | D22: Danni | E22: =IF(AND(COUNTIF(F22:J22,"X")>0,COUNTIF(K22:O22,"X")>0,COUNTIF(P22:T22,"X")>0),"X","") -> X | F22: X | N22: X | O22: X | Q22: X | R22: X
A23: https://doi.org/10.1145/3772318.3790934 | B23: 10.1145/3772318.3790934 | C23: Does Sycophancy Change Decisions? Effect of LLM Sycophancy on AI-Assisted Decision-Making | D23: Danni | E23: =IF(AND(COUNTIF(F23:J23,"X")>0,COUNTIF(K23:O23,"X")>0,COUNTIF(P23:T23,"X")>0),"X","") -> X | F23: X | L23: X | M23: X | Q23: X | R23: X | T23: X
A24: https://doi.org/10.1145/3772318.3791079 | B24: 10.1145/3772318.3791079 | C24: Be Friendly | D24: Danni | E24: =IF(AND(COUNTIF(F24:J24,"X")>0,COUNTIF(K24:O24,"X")>0,COUNTIF(P24:T24,"X")>0),"X","") -> X | F24: X | M24: X | N24: X | Q24: X
A25: https://doi.org/10.1145/3772318.3791149 | B25: 10.1145/3772318.3791149 | C25: The Siren Song of LLMs: How Users Perceive and Respond to Dark Patterns in Large Language Models | D25: Jonathan | E25: =IF(AND(COUNTIF(F25:J25,"X")>0,COUNTIF(K25:O25,"X")>0,COUNTIF(P25:T25,"X")>0),"X","") -> X | F25: X | L25: X | M25: X | Q25: X | R25: X
A26: https://doi.org/10.1145/3772318.3791233 | B26: 10.1145/3772318.3791233 | C26: When AI Gives Advice: Evaluating AI and Human Responses to Online Advice-Seeking for Well-Being | D26: Jonathan | E26: =IF(AND(COUNTIF(F26:J26,"X")>0,COUNTIF(K26:O26,"X")>0,COUNTIF(P26:T26,"X")>0),"X","") -> X | G26: X | H26: X | L26: X | Q26: X | S26: X
A27: https://doi.org/10.1145/3772318.3791300 | B27: 10.1145/3772318.3791300 | C27: All Accept | D27: Jonathan | E27: =IF(AND(COUNTIF(F27:J27,"X")>0,COUNTIF(K27:O27,"X")>0,COUNTIF(P27:T27,"X")>0),"X","") -> X | H27: X | L27: X | S27: X
A28: https://doi.org/10.1145/3772318.3791365 | B28: 10.1145/3772318.3791365 | C28: Invisible Saboteurs: Sycophantic LLMs Mislead Novices in Problem-Solving Tasks | D28: Jonathan | E28: =IF(AND(COUNTIF(F28:J28,"X")>0,COUNTIF(K28:O28,"X")>0,COUNTIF(P28:T28,"X")>0),"X","") -> X | G28: X | O28: X | T28: X
A29: https://doi.org/10.1145/3772318.3791851 | B29: 10.1145/3772318.3791851 | C29: Personal Validation Effect in LLMs: Positive AI Responses Bias Perceptions of Validity | D29: Jonathan | E29: =IF(AND(COUNTIF(F29:J29,"X")>0,COUNTIF(K29:O29,"X")>0,COUNTIF(P29:T29,"X")>0),"X","") -> X | F29: X | L29: X | Q29: X
A30: https://doi.org/10.1145/3772318.3791915 | B30: 10.1145/3772318.3791915 | C30: Interaction Context Often Increases Sycophancy in LLMs | D30: Jonathan | E30: =IF(AND(COUNTIF(F30:J30,"X")>0,COUNTIF(K30:O30,"X")>0,COUNTIF(P30:T30,"X")>0),"X","") -> X | G30: X | L30: X | P30: X
A31: https://doi.org/10.1145/3772363.3798705 | B31: 10.1145/3772363.3798705 | C31: When AI Agrees | D31: Jonathan | E31: =IF(AND(COUNTIF(F31:J31,"X")>0,COUNTIF(K31:O31,"X")>0,COUNTIF(P31:T31,"X")>0),"X","") -> X | F31: X | L31: X | Q31: X
A32: https://doi.org/10.1145/3772363.3799334 | B32: 10.1145/3772363.3799334 | C32: Maintaining Stable Personas? Examining Temporal Stability in LLM-Based Human Simulation | D32: Kaiser | E32: =IF(AND(COUNTIF(F32:J32,"X")>0,COUNTIF(K32:O32,"X")>0,COUNTIF(P32:T32,"X")>0),"X","") -> X | I32: X | O32: X | S32: X
A33: https://doi.org/10.1145/3774904.3792506 | B33: 10.1145/3774904.3792506 | C33: Acting Flatterers via LLMs Sycophancy: Combating Clickbait with LLMs Opposing-Stance Reasoning | D33: Kaiser | E33: =IF(AND(COUNTIF(F33:J33,"X")>0,COUNTIF(K33:O33,"X")>0,COUNTIF(P33:T33,"X")>0),"X","") -> X | J33: X | L33: X | N33: X | S33: X
A34: https://doi.org/10.1145/3776734.3794532 | B34: 10.1145/3776734.3794532 | C34: Robotic Sycophancy: A Scoping Review | D34: Kaiser | E34: =IF(AND(COUNTIF(F34:J34,"X")>0,COUNTIF(K34:O34,"X")>0,COUNTIF(P34:T34,"X")>0),"X","") -> X | I34: X | L34: X | M34: X | O34: X | P34: X
A35: https://doi.org/10.1145/3786304.3787879 | B35: 10.1145/3786304.3787879 | C35: Confirmation | D35: Kaiser | E35: =IF(AND(COUNTIF(F35:J35,"X")>0,COUNTIF(K35:O35,"X")>0,COUNTIF(P35:T35,"X")>0),"X","") -> X | I35: X | L35: X | P35: X
A36: https://doi.org/10.1145/3786335.3813137 | B36: 10.1145/3786335.3813137 | C36: The Cost of Consensus: Isolated Self-Correction Prevails Over Unguided Homogeneous Multi-Agent Debate | D36: Kaiser | E36: =IF(AND(COUNTIF(F36:J36,"X")>0,COUNTIF(K36:O36,"X")>0,COUNTIF(P36:T36,"X")>0),"X","") -> X | I36: X | N36: X | S36: X
